<?xml version="1.0" ?>
<!-- =================================================================================== -->
<!-- |    This document was autogenerated by xacro from talos_full.urdf.xacro          | -->
<!-- |    EDITING THIS FILE BY HAND IS NOT RECOMMENDED                                 | -->
<!-- =================================================================================== -->
<!--

  Copyright (c) 2016, PAL Robotics, S.L.
  All rights reserved.

  This work is licensed under the Creative Commons Attribution-NonCommercial-NoDerivs 3.0 Unported License.
  To view a copy of this license, visit http://creativecommons.org/licenses/by-nc-nd/3.0/ or send a letter to
  Creative Commons, 444 Castro Street, Suite 900, Mountain View, California, 94041, USA.
-->
<robot name="talos" xmlns:controller="http://playerstage.sourceforge.net/gazebo/xmlschema/#controller" xmlns:interface="http://playerstage.sourceforge.net/gazebo/xmlschema/#interface" xmlns:sensor="http://playerstage.sourceforge.net/gazebo/xmlschema/#sensor" xmlns:xacro="http://ros.org/wiki/xacro">
  <!--File includes-->
  <!--Constant parameters-->
  <!--File includes-->
  <!-- Macro -->
  <!--Constant parameters-->
  <!--************************-->
  <!--     HEAD_1 (TILT)      -->
  <!--************************-->
  <!--************************-->
  <!--      HEAD_2 (PAN)      -->
  <!--************************-->
  <!--File includes-->
  <!--File includes-->
  <!--Constant parameters-->
  <!--Constant parameters-->
  <!--File includes-->
  <!-- VIRTUAL (mimic) JOINTS -->
  <!-- 0.45deg -->
  <!--************************-->
  <!--        TORSO_2  (TILT) -->
  <!--************************-->
  <link name="torso_2_link">
    <inertial>
      <origin rpy="0.00000 0.00000 0.00000" xyz="-0.04551 -0.00053 0.16386"/>
      <mass value="17.55011"/>
      <inertia ixx="0.37376900000" ixy="0.00063900000" ixz="0.01219600000" iyy="0.24790200000" iyz="0.00000700000" izz="0.28140400000"/>
    </inertial>
    <visual>
      <origin rpy="0 0 0" xyz="0 0 0"/>
      <geometry>
        <mesh filename="package://meshes/torso/torso_2.STL" scale="1 1 1"/>
      </geometry>
      <material name="LightGrey"/>
    </visual>
    <collision>
      <origin rpy="0 0 0" xyz="0 0 0"/>
      <geometry>
        <mesh filename="package://meshes/torso/torso_2_collision.STL" scale="1 1 1"/>
      </geometry>
    </collision>
  </link>
  <!--************************-->
  <!--        TORSO_1  (PAN)  -->
  <!--************************-->
  <link name="torso_1_link">
    <inertial>
      <origin rpy="0.00000 0.00000 0.00000" xyz="0.00013 -0.00001 -0.01306"/>
      <mass value="3.02433"/>
      <inertia ixx="0.00759400000" ixy="0.00000100000" ixz="-0.00004800000" iyy="0.00429200000" iyz="-0.00000100000" izz="0.00749700000"/>
    </inertial>
    <visual>
      <origin rpy="0 0 0" xyz="0 0 0"/>
      <geometry>
        <mesh filename="package://meshes/torso/torso_1.STL" scale="1 1 1"/>
      </geometry>
      <material name="LightGrey"/>
    </visual>
    <collision>
      <origin rpy="0 0 0" xyz="0 0 0"/>
      <geometry>
        <mesh filename="package://meshes/torso/torso_1.STL" scale="1 1 1"/>
      </geometry>
    </collision>
  </link>
  <joint name="torso_1_joint" type="revolute">
    <parent link="base_link"/>
    <child link="torso_1_link"/>
    <origin rpy="0.0 0.0 0.0" xyz="0.0 0.0 0.0722"/>
    <axis xyz="0 0 1"/>
    <limit effort="78.0" lower="-1.308996939" upper="1.308996939" velocity="5.4"/>
    <dynamics damping="1.0" friction="1.0"/>
    <!-- <safety_controller k_position="20"
                         k_velocity="20"
                         soft_lower_limit="${-15.0 * deg_to_rad + torso_eps}"
                         soft_upper_limit="${ 45.0 * deg_to_rad - torso_eps}" /> -->
  </joint>
  <!--************************-->
  <!--        BASE_LINK       -->
  <!--************************-->
  <link name="base_link">
    <inertial>
      <origin rpy="0.00000 0.00000 0.00000" xyz="-0.08222 0.00838 -0.07261"/>
      <mass value="13.53810"/>
      <inertia ixx="0.06989000000" ixy="-0.00011700000" ixz="0.00023000000" iyy="0.03998200000" iyz="-0.00132500000" izz="0.08234500000"/>
    </inertial>
    <visual>
      <origin rpy="0 0 0" xyz="0 0 0"/>
      <geometry>
        <mesh filename="package://meshes/torso/base_link.STL" scale="1 1 1"/>
      </geometry>
      <material name="LightGrey"/>
    </visual>
    <collision>
      <origin rpy="0 0 0" xyz="0 0 0"/>
      <geometry>
        <mesh filename="package://meshes/torso/base_link_collision.STL" scale="1 1 1"/>
      </geometry>
    </collision>
  </link>
  <joint name="torso_2_joint" type="revolute">
    <parent link="torso_1_link"/>
    <child link="torso_2_link"/>
    <origin rpy="0.0 0.0 0.0" xyz="0.0 0.0 0.0"/>
    <axis xyz="0 1 0"/>
    <limit effort="78.0" lower="-0.261799387799" upper="0.785398163397" velocity="5.4"/>
    <dynamics damping="1.0" friction="1.0"/>
    <!-- <safety_controller k_position="20"
                          k_velocity="20"
                          soft_lower_limit="${-75.00000 * deg_to_rad + eps_radians}"
                          soft_upper_limit="${75.00000 * deg_to_rad - eps_radians}" /> -->
  </joint>

  <!--************************-->
  <!--        SHOULDER        -->
  <!--************************-->
  <link name="arm_left_1_link">
    <!-- TODO: Missing reflects of inertias -->
    <inertial>
      <origin rpy="0.00000 0.00000 0.00000" xyz="-0.01346 0.0913 0.04812"/>
      <!-- <mass value="1.52896"/> -->
      <mass value="1.42896"/>
      <inertia ixx="0.00555100000" ixy="-0.00073100000" ixz="0.00000800000" iyy="0.00167300000" iyz="-0.00006000000" izz="0.00582200000"/>
    </inertial>
    <visual>
      <origin rpy="0 0 0" xyz="0 0 0"/>
      <geometry>
        <mesh filename="package://meshes/arm/arm_1_collision.STL" scale="1 1 1"/>
      </geometry>
      <material name="DarkGrey"/>
    </visual>
    <collision>
      <origin rpy="0 0 0" xyz="0 0 0"/>
      <geometry>
        <mesh filename="package://meshes/arm/arm_1_collision.STL" scale="1 1 1"/>
      </geometry>
    </collision>
  </link>
  <joint name="arm_left_1_joint" type="revolute">
    <parent link="torso_2_link"/>
    <child link="arm_left_1_link"/>
    <origin rpy="0.0 0.0 0.0" xyz="0.00000 0.1575 0.23200"/>
    <axis xyz="0 0 1"/>
    <limit effort="44.64" lower="-1.57079632679" upper="0.523598775598" velocity="2.7"/>
    <dynamics damping="1.0" friction="1.0"/>
    <!--        <safety_controller k_position="20"
                          k_velocity="20"
                          soft_lower_limit="${-90.00000 * deg_to_rad + arm_eps}"
                          soft_upper_limit="${30.00000 * deg_to_rad - arm_eps}" /> -->
  </joint>
  <link name="arm_left_2_link">
    <inertial>
      <origin rpy="0.00000 0.00000 0.00000" xyz="0.02607 0.00049 -0.05209"/>
      <!-- <mass value="1.77729"/> -->
      <mass value="1.67729"/>
      <inertia ixx="0.00708700000" ixy="-0.00001400000" ixz="0.00214200000" iyy="0.00793600000" iyz="0.00003000000" izz="0.00378800000"/>
    </inertial>
    <visual>
      <origin rpy="0 0 0" xyz="0 0 0"/>
      <geometry>
        <mesh filename="package://meshes/arm/arm_2_collision.STL" scale="1 1 1"/>
      </geometry>
      <material name="DarkGrey"/>
    </visual>
    <collision>
      <origin rpy="0 0 0" xyz="0 0 0"/>
      <geometry>
        <mesh filename="package://meshes/arm/arm_2_collision.STL" scale="1 1 1"/>
      </geometry>
    </collision>
  </link>
  <joint name="arm_left_2_joint" type="revolute">
    <parent link="arm_left_1_link"/>
    <child link="arm_left_2_link"/>
    <origin rpy="0.0 0.0 0.0" xyz="0.00493 0.1365 0.04673"/>
    <axis xyz="1 0 0"/>
    <limit effort="22.32" lower="0.0" upper="2.87979326579" velocity="3.66"/>
    <dynamics damping="1.0" friction="1.0"/>
    <!--        <safety_controller k_position="20"
                          k_velocity="20"
                          soft_lower_limit="${0.00000 * deg_to_rad + arm_eps}"
                          soft_upper_limit="${165.00000 * deg_to_rad - arm_eps}" /> -->
  </joint>
  <link name="arm_left_3_link">
    <inertial>
      <origin rpy="0.00000 0.00000 0.00000" xyz="0.00841 0.01428 -0.22291"/>
      <!-- <mass value="1.57029"/> -->
      <mass value="1.47029"/>
      <inertia ixx="0.00433200000" ixy="0.00015300000" ixz="-0.00049600000" iyy="0.00434000000" iyz="-0.00060900000" izz="0.00254300000"/>
    </inertial>
    <visual>
      <origin rpy="0 0 0" xyz="0 0 0"/>
      <geometry>
        <mesh filename="package://meshes/arm/arm_3_collision.STL" scale="1 1 1"/>
      </geometry>
      <material name="DarkGrey"/>
    </visual>
    <collision>
      <origin rpy="0 0 0" xyz="0 0 0"/>
      <geometry>
        <mesh filename="package://meshes/arm/arm_3_collision.STL" scale="1 1 1"/>
      </geometry>
    </collision>
  </link>
  <joint name="arm_left_3_joint" type="revolute">
    <parent link="arm_left_2_link"/>
    <child link="arm_left_3_link"/>
    <origin rpy="0.0 0.0 0.0" xyz="0.00000 0.00000 0.00000"/>
    <axis xyz="0 0 1"/>
    <limit effort="17.86" lower="-2.44346095279" upper="2.44346095279" velocity="4.58"/>
    <dynamics damping="1.0" friction="1.0"/>
    <!--       <safety_controller k_position="20"
                          k_velocity="20"
                          soft_lower_limit="${-140.0 * deg_to_rad + arm_eps}"
                          soft_upper_limit="${140.0 * deg_to_rad - arm_eps}" /> -->
  </joint>
  <!--************************-->
  <!--        ELBOW           -->
  <!--************************-->
  <link name="arm_left_4_link">
    <inertial>
      <origin rpy="0.00000 0.00000 0.00000" xyz="-0.00655 -0.02107 -0.02612"/>
      <!-- <mass value="1.20216"/> -->
      <mass value="1.10216"/>
      <inertia ixx="0.00221700000" ixy="-0.00010100000" ixz="0.00028800000" iyy="0.00241800000" iyz="-0.00039300000" izz="0.00111500000"/>
    </inertial>
    <visual>
      <origin rpy="0 0 0" xyz="0 0 0"/>
      <geometry>
        <mesh filename="package://meshes/arm/arm_4_collision.STL" scale="1 1 1"/>
      </geometry>
      <material name="DarkGrey"/>
    </visual>
    <collision>
      <origin rpy="0 0 0" xyz="0 0 0"/>
      <geometry>
        <mesh filename="package://meshes/arm/arm_4_collision.STL" scale="1 1 1"/>
      </geometry>
    </collision>
  </link>
  <joint name="arm_left_4_joint" type="revolute">
    <parent link="arm_left_3_link"/>
    <child link="arm_left_4_link"/>
    <origin rpy="0.0 0.0 0.0" xyz="0.02000 0.00000 -0.27300"/>
    <axis xyz="0 1 0"/>
    <limit effort="17.86" lower="-2.35619449019" upper="0.0" velocity="4.58"/>
    <dynamics damping="1.0" friction="1.0"/>
    <!--       <safety_controller k_position="20"
                          k_velocity="20"
                          soft_lower_limit="${-135.0 * deg_to_rad + arm_eps}"
                          soft_upper_limit="${0.0 * deg_to_rad - arm_eps}" /> -->
  </joint>

  <!--************************-->
  <!--        WRIST           -->
  <!--************************-->
  <!--************************-->
  <!--        WRIST           -->
  <!--************************-->
  <link name="arm_left_5_link">
    <inertial>
      <origin rpy="0.00000 0.00000 0.00000" xyz="-0.00006 0.00326 0.07963"/>
      <!-- <mass value="1.87792"/> -->
      <mass value="1.77792"/>
      <inertia ixx="0.00349500000" ixy="-0.00001300000" ixz="-0.00001000000" iyy="0.00436800000" iyz="0.00009700000" izz="0.00228300000"/>
    </inertial>
    <visual>
      <origin rpy="0 0 0" xyz="0 0 0"/>
      <geometry>
        <mesh filename="package://meshes/arm/arm_5_collision.STL" scale="1 1 1"/>
      </geometry>
      <material name="LightGrey"/>
    </visual>
    <collision>
      <origin rpy="0 0 0" xyz="0 0 0"/>
      <geometry>
        <mesh filename="package://meshes/arm/arm_5_collision.STL" scale="1 1 1"/>
      </geometry>
    </collision>
  </link>
  <joint name="arm_left_5_joint" type="revolute">
    <parent link="arm_left_4_link"/>
    <child link="arm_left_5_link"/>
    <origin rpy="0.0 0.0 0.0" xyz="-0.02000 0.00000 -0.26430"/>
    <axis xyz="0 0 1"/>
    <limit effort="3" lower="-2.53072741539" upper="2.53072741539" velocity="1.95"/>
    <dynamics damping="1.0" friction="1.0"/>
    <!--       <safety_controller k_position="20"
                          k_velocity="20"
                          soft_lower_limit="${-145.00000 * deg_to_rad + wrist_eps}"
                          soft_upper_limit="${145.00000 * deg_to_rad - wrist_eps}" /> -->
  </joint>
  <link name="arm_left_6_link">
    <inertial>
      <origin rpy="0.00000 0.00000 0.00000" xyz="0.00002 -0.00197 -0.00059"/>
      <!-- <mass value="0.40931"/> -->
      <mass value="0.30931"/>
      <inertia ixx="0.00010700000" ixy="0.00000000000" ixz="0.00000000000" iyy="0.00014100000" iyz="-0.00000000000" izz="0.00015400000"/>
    </inertial>
    <visual>
      <origin rpy="0 0 0" xyz="0 0 0"/>
      <geometry>
        <mesh filename="package://meshes/arm/arm_6_collision.STL" scale="1 1 1"/>
      </geometry>
      <material name="LightGrey"/>
    </visual>
    <collision>
      <origin rpy="0 0 0" xyz="0 0 0"/>
      <geometry>
        <mesh filename="package://meshes/arm/arm_6_collision.STL" scale="1 1 1"/>
      </geometry>
    </collision>
  </link>
  <joint name="arm_left_6_joint" type="revolute">
    <parent link="arm_left_5_link"/>
    <child link="arm_left_6_link"/>
    <origin rpy="0.0 0.0 0.0" xyz="0.00000 0.00000 0.00000"/>
    <axis xyz="1 0 0"/>
    <limit effort="6.6" lower="-1.3962634016" upper="1.3962634016" velocity="1.76"/>
    <dynamics damping="1.0" friction="1.0"/>
    <!--       <safety_controller k_position="20"
                          k_velocity="20"
                          soft_lower_limit="${-80.00000 * deg_to_rad + eps_radians}"
                          soft_upper_limit="${80.00000 * deg_to_rad - eps_radians}" /> -->
  </joint>
  <link name="arm_left_7_link">
    <!-- WRONG VALUES
      <inertial>
        <origin xyz="-0.00089 0.00365 -0.07824" rpy="0.00000 0.00000 0.00000"/>
        <mass value="1.02604"/>
        <inertia ixx="0.00151400000" ixy="0.00000600000" ixz="0.00006600000"
                 iyy="0.00146400000" iyz="0.00001200000"
                 izz="0.00090300000"/>
      </inertial>
      -->
    <inertial>
      <origin rpy="0.00000 0.00000 0.00000" xyz="0.007525 0.001378 -0.024630"/>
      <mass value="0.308441"/>
      <inertia ixx="0.000309" ixy="0.000002" ixz="-0.000002" iyy="0.000219" iyz="0.000012" izz="0.000176"/>
    </inertial>
    <visual>
      <origin rpy="0 0 0" xyz="0 0 0"/>
      <geometry>
        <mesh filename="package://meshes/arm/arm_7.STL" scale="1 1 1"/>
      </geometry>
      <material name="DarkGrey"/>
    </visual>
    <collision>
      <origin rpy="0 0 0" xyz="0 0 0"/>
      <geometry>
        <mesh filename="package://meshes/arm/arm_7_collision.STL" scale="1 1 1"/>
      </geometry>
    </collision>
  </link>
  <joint name="arm_left_7_joint" type="revolute">
    <parent link="arm_left_6_link"/>
    <child link="arm_left_7_link"/>
    <origin rpy="0.0 0.0 0.0" xyz="0.0 0.0 0.0"/>
    <axis xyz="0 1 0"/>
    <limit effort="6.6" lower="-0.698131700798" upper="0.698131700798" velocity="1.76"/>
    <dynamics damping="1.0" friction="1.0"/>
    <!--       <safety_controller k_position="20"
                          k_velocity="20"
                          soft_lower_limit="${-40.00000 * deg_to_rad + eps_radians}"
                          soft_upper_limit="${40.00000 * deg_to_rad - eps_radians}" /> -->
  </joint>


  <!--************************-->
  <!--        ft sensor       -->
  <!--************************-->
  <link name="wrist_left_ft_link">
    <inertial>
      <mass value="0.1"/>
      <inertia ixx="0.0" ixy="0.0" ixz="0.0" iyy="0.0" iyz="0.0" izz="0.0"/>
    </inertial>
    <visual>
      <origin rpy="0 0 0" xyz="0 0 0"/>
      <geometry>
        <cylinder length="0.0157" radius="0.0225"/>
      </geometry>
      <material name="LightGrey"/>
    </visual>
    <collision>
      <origin rpy="0 0 0" xyz="0 0 0"/>
      <geometry>
        <cylinder length="0.0157" radius="0.0225"/>
      </geometry>
    </collision>
  </link>
  <joint name="wrist_left_ft_joint" type="fixed">
    <parent link="arm_left_7_link"/>
    <child link="wrist_left_ft_link"/>
    <origin rpy="0.0 0 -4.71238898038" xyz="0 0 -0.051"/>
  </joint>
  <!--***********************-->
  <!--       FT TOOL         -->
  <!--***********************-->
  <!--<link name="wrist_left_ft_tool_link">
    <inertial>
      <mass value="0.1"/>
      <inertia ixx="0.0" ixy="0.0" ixz="0.0" iyy="0.0" iyz="0.0" izz="0.0"/>
    </inertial>
    <visual>
      <origin rpy="0 0.0 0" xyz="0.0 0 0"/>
      <geometry>
        <cylinder length="0.00975" radius="0.025"/>
      </geometry>
      <material name="FlatBlack"/>
    </visual>
    <collision>
      <origin rpy="0 0.0 0" xyz="0.0 0 0"/>
      <geometry>
        <cylinder length="0.00975" radius="0.025"/>
      </geometry>
    </collision>
  </link>
  <joint name="wrist_left_tool_joint" type="fixed">
    <parent link="wrist_left_ft_link"/>
    <child link="wrist_left_ft_tool_link"/>
    <origin rpy="0 0 4.71238898038" xyz="0 0 -0.012725"/>
  </joint>
  <link name="gripper_left_base_link">
    <inertial>
      <origin rpy="0.00000 0.00000 0.00000" xyz="-0.00534 0.00362 -0.02357"/>
      <mass value="0.61585"/>
      <inertia ixx="0.00047200000" ixy="-0.00000800000" ixz="0.00003500000" iyy="0.00052100000" iyz="0.00000000000" izz="0.00069000000"/>
    </inertial>
    <visual>
      <origin rpy="0 0 0" xyz="0 0 0"/>
      <geometry>
        <mesh filename="package://meshes/gripper/base_link.STL" scale="1 1 1"/>
      </geometry>
      <material name="DarkGrey"/>
    </visual>
    <collision>
      <origin rpy="0 0 0" xyz="0 0 0"/>
      <geometry>
        <mesh filename="package://meshes/gripper/base_link_collision.STL" scale="1 1 1"/>
      </geometry>
    </collision>
  </link>
  <joint name="gripper_left_base_link_joint" type="fixed">
    <parent link="wrist_left_ft_tool_link"/>
    <child link="gripper_left_base_link"/>
    <origin rpy="0.0 0.0 0.0" xyz="0.00000 0.00000 -0.02875"/>
    <axis xyz="0 0 0"/>
  </joint>
  <link name="gripper_left_motor_double_link">
    <inertial>
      <origin rpy="0.00000 0.00000 0.00000" xyz="0.02270 0.01781 -0.00977"/>
      <mass value="0.16889"/>
      -->
      <!-- In order for Gazebo not to explode we needed to add these 0.001 values to the diagonal,
                also the tool pal_dynamics InertiaMassVisualization gave NaN on the computation of the inertia box -->
      <!--<inertia ixx="0.001159" ixy="-0.00007000000" ixz="0.00003800000" iyy="0.001221" iyz="-0.00005300000" izz="0.001268"/>
    </inertial>
    <visual>
      <origin rpy="0 0 0" xyz="0 0 0"/>
      <geometry>
        <mesh filename="package://meshes/gripper/gripper_motor_double.STL" scale="1 1 1"/>
      </geometry>
      <material name="Orange"/>
    </visual>
    <collision>
      <origin rpy="0 0 0" xyz="0 0 0"/>
      <geometry>
        <mesh filename="package://meshes/gripper/gripper_motor_double_collision.STL" scale="1 1 1"/>
      </geometry>
    </collision>
  </link>
  <joint name="gripper_left_joint" type="revolute">
    <parent link="gripper_left_base_link"/>
    <child link="gripper_left_motor_double_link"/>
    <origin rpy="0.0 0.0 0.0" xyz="0.0 0.02025 -0.03"/>
    <axis xyz="1 0 0"/>
    <limit effort="1.0" lower="-1.0471975512" upper="0.0" velocity="1.0"/>
    <dynamics damping="1.0" friction="1.0"/>
  </joint>
  <link name="gripper_left_inner_double_link">
    <inertial>
      <origin rpy="0.00000 0.00000 0.00000" xyz="-0.00056 0.03358 -0.01741"/>
      <mass value="0.11922"/>
      <inertia ixx="0.00009100000" ixy="0.00000100000" ixz="-0.00000100000" iyy="0.00015600000" iyz="-0.00003200000" izz="0.00012600000"/>
    </inertial>
    <visual>
      <origin rpy="0 0 0" xyz="0 0 0"/>
      <geometry>
        <mesh filename="package://meshes/gripper/inner_double.STL" scale="1 1 1"/>
      </geometry>
      <material name="Orange"/>
    </visual>
    <collision>
      <origin rpy="0 0 0" xyz="0 0 0"/>
      <geometry>
        <mesh filename="package://meshes/gripper/inner_double_collision.STL" scale="1 1 1"/>
      </geometry>
    </collision>
  </link>
  -->

  <!-- virtual mimic joints -->
  <!--         <xacro:gripper_virtual_transmission name="${name}_inner_double" reduction="1.0"/>
        <xacro:gripper_virtual_transmission name="${name}_fingertip_1" reduction="1.0"/>
        <xacro:gripper_virtual_transmission name="${name}_fingertip_2" reduction="1.0"/>
        <xacro:gripper_virtual_transmission name="${name}_inner_single" reduction="1.0"/>
        <xacro:gripper_virtual_transmission name="${name}_motor_single" reduction="1.0"/>
        <xacro:gripper_virtual_transmission name="${name}_fingertip_3" reduction="1.0"/> -->


  <!-- define global properties -->
  <!-- <xacro:property name="M_PI" value="3.1415926535897931" /> -->
  <!-- Materials for visualization -->
  <material name="Blue">
    <color rgba="0.0 0.0 0.8 1.0"/>
  </material>
  <material name="Green">
    <color rgba="0.0 0.8 0.0 1.0"/>
  </material>
  <material name="Grey">
    <color rgba="0.7 0.7 0.7 1.0"/>
  </material>
  <material name="LightGrey">
    <color rgba="0.9 0.9 0.9 1.0"/>
  </material>
  <material name="DarkGrey">
    <color rgba="0.2 0.2 0.2 1.0"/>
  </material>
  <material name="FlatBlack">
    <color rgba="0. 0. 0. 1.0"/>
  </material>
  <material name="Red">
    <color rgba="0.8 0.0 0.0 1.0"/>
  </material>
  <material name="White">
    <color rgba="1.0 1.0 1.0 1.0"/>
  </material>
  <material name="Orange">
    <color rgba="1.0 0.5 0.0 1.0"/>
  </material>
</robot>

